Workbook

Sheet Key Assumptions
A1: IEPPAL — KEY MODEL ASSUMPTIONS
A2: All assumptions drawn from the individual scenario sheets.
A4: Category | B4: Assumption | C4: Value / Formula | D4: Unit | E4: Source / Rationale
A5: Pricing | B5: Basic Package — Annual Base Fee | C5: S$3,000 | E5: Benchmark vs EdTech SaaS comps
A6: Pricing | B6: Basic IEP Access Fee / Student | C6: S$12
A7: Pricing | B7: Basic AI Tool Fee / Student | C7: S$15 | E7: Founder assumption; applied to 50% of IEP students to incentivize Schools Package
A8: Pricing | B8: Schools Package — Annual Base Fee | C8: S$5,000 | E8: Benchmark vs EdTech SaaS comps
A9: Pricing | B9: Schools IEP Access Fee / Student | C9: S$12
A10: Pricing | B10: Schools AI Tool Fee / Student | C10: S$12 | E10: Founder assumption; Falling cost for higher SaaS tier
A11: Pricing | B11: Custom Package — Annual Base Fee | C11: S$20,000 | E11: White-label, Enterprise; Inclusion of Custom Development & Early Access
A12: Pricing | B12: Custom IEP Access Fee / Student | C12: S$12
A13: Pricing | B13: Custom AI Tool Fee / Student | C13: S$10 | E13: Founder assumption; Falling cost for higher SaaS tier
A15: Growth | B15: Custom Package — first client onboarded | C15: Y2 Q2 | E15: Conservative; dependent on enterprise sales cycle
A16: Churn | B16: Quarterly gross churn rate (base case) | C16: 0.05 | E16: Conservative; EdTech avg ≈ 3–8% / quarter
A17: Churn | B17: Net Expansion Rate (base case) | C17: 0.08 | E17: Schools add more students over contract life
A19: Cost | B19: Software Engineer salary (India) | C19: S$3,400 | E19: Market rate India senior SWE, Jun 2026
A20: Cost | B20: Marketing Manager salary (India) | C20: S$4,750 | E20: Market rate India, Jun 2026
A21: Cost | B21: Sales & Partnership salary | C21: S$8,000 | E21: Market rate Singapore, Jun 2026
A22: Cost | B22: Annual Pen-test + Security upkeep | C22: S$10,000 | E22: SG security firm quote; = S$2,500/quarter
A23: Cost | B23: GDPR compliance (Y1 / Y2+) | C23: S$20,000 / S$10,000 | E23: External GDPR consultant; decreases after initial setup
A24: Cost | B24: AWS Cloud (Q1 actual — 4 test users) | C24: S$37.44 | E24: Actual AWS billing for RASA prototype; optimised post-go-live
A26: Funding | B26: Pre-seed raise (assumed for runway model) | C26: 185000 | D26: Covers Y1+Y2 total costs (S$165,537) + 12% buffer. Re-run after churn correction. | E26: ⚠ PLACEHOLDER — update with actual raise amount before investor meetings
A27: Funding | B27: Target close date | C27: Y1 Q1 | D27: Update with actual close date before investor meetings | E27: ⚠ PLACEHOLDER — update with actual timeline
A28: Funding | B28: Raise currency | C28: SGD
A30: AI Cost | B30: Avg IEP queries per student per day | C30: 12 | D30: Covers queries to AI generate IEPs, Goals, Surveys, & perform data analytics + strategy recommendations
A31: AI Cost | B31: Avg tokens per query (input + output) | C31: 4000 | D31: Full IEP context window; conservative estimate
A32: AI Cost | B32: API cost per million tokens (SGD) | C32: 0.37 | D32: GPT-4o-mini at $0.25/M × 1.35 USD/SGD; update to actual model used
A33: AI Cost | B33: Queries per 3 months | C33: 360 | D33: Fixed
A35: Seasonality | B35: Q1 (Jan-Mar) weight | C35: 0.7 | D35: Second semester
A36: Seasonality | B36: Q2 (Apr-Jun) weight | C36: 1.3 | D36: Proposal submissions for following school year
A37: Seasonality | B37: Q3 (Jul-Sep) weight | C37: 1.1 | D37: Proposal submissions for following school year
A38: Seasonality | B38: Q4 (Oct-Dec) weight | C38: 0.9 | D38: First semester
A39: Seasonality | B39: Application note | C39: Applies to new account wins only — not churn or expansion ARR

Sheet Income Statement
A1: FINANCIAL FORECAST (3 YEARS)
B2: YEAR 1 | F2: YEAR 2 | J2: YEAR 3 | N2: Assumptions
B3: Q1 | C3: Q2 | D3: Q3 | E3: Q4 | F3: Q1 | G3: Q2 | H3: Q3 | I3: Q4 | J3: Q1 | K3: Q2 | L3: Q3 | M3: Q4
A4: REVENUE FORECAST
A5: OPERATING REVENUES (Primary Business Income)
A7: Basic Package Subscription (Standard Fees)
A8: Annual Base Fee ($3000 Annually) | B8: 750 | C8: 750 | D8: 750 | E8: 750 | F8: 750 | G8: 750 | H8: 750 | I8: 750 | J8: 750 | K8: 750 | L8: 750 | M8: 750
A9: IEP Access Fee Per Student | B9: 15 | C9: 15 | D9: 15 | E9: 15 | F9: 15 | G9: 15 | H9: 15 | I9: 15 | J9: 15 | K9: 15 | L9: 15 | M9: 15 | N9: IEP & AI cost per student stay constant
A10: Number of Students | B10: 20 | C10: 20 | D10: 30 | E10: 40 | F10: 45 | G10: 50 | H10: 60 | I10: 80 | J10: 100 | K10: 120 | L10: 160 | M10: 180
A11: AI Tool Pricing Per Student | B11: 15 | C11: 15 | D11: 15 | E11: 15 | F11: 15 | G11: 15 | H11: 15 | I11: 15 | J11: 15 | K11: 15 | L11: 15 | M11: 15 | N11: IEP & AI cost per student stay constant
A12: Number of Students (50% of IEP students) | B12: =B10/2 -> 10 | C12: =C10/2 -> 10 | D12: =D10/2 -> 15 | E12: =E10/2 -> 20 | F12: =F10/2 -> 22.5 | G12: =G10/2 -> 25 | H12: =H10/2 -> 30 | I12: =I10/2 -> 40 | ... M12: =M10/2 -> 90
A13: Total IEP Fees | B13: =SUM(B8,PRODUCT(B9,B10),PRODUCT(B11,B12)) -> 1200 | C13: =SUM(C8,PRODUCT(C9,C10),PRODUCT(C11,C12)) -> 1200 | D13: =SUM(D8,PRODUCT(D9,D10),PRODUCT(D11,D12)) -> 1425 | E13: =SUM(E8,PRODUCT(E9,E10),PRODUCT(E11,E12)) -> 1650 | F13: =SUM(F8,PRODUCT(F9,F10),PRODUCT(F11,F12)) -> 1762.5 | G13: =SUM(G8,PRODUCT(G9,G10),PRODUCT(G11,G12)) -> 1875 | H13: =SUM(PRODUCT(H9,H10),PRODUCT(H11,H12),SUM(H8)) -> 2100 | I13: =SUM(PRODUCT(I9,I10),PRODUCT(I11,I12),SUM(I8)) -> 2550 | J13: =SUM(PRODUCT(J9,J10),PRODUCT(J11,J12),SUM(J8)) -> 3000 | K13: =SUM(PRODUCT(K9,K10),PRODUCT(K11,K12),SUM(K8)) -> 3450 | L13: =SUM(PRODUCT(L9,L10),PRODUCT(L11,L12),SUM(L8)) -> 4350 | M13: =SUM(PRODUCT(M9,M10),PRODUCT(M11,M12),SUM(M8)) -> 4800
A14: Additional Add-ons: Data Migration, Strategy Library, PD Offerings
A15: Strategy Library Subscription Fee (Monthly Recurring) | B15: 99 | C15: 99 | D15: 99 | E15: 99 | F15: 99 | G15: 99 | H15: 99 | I15: 99 | J15: 99 | K15: 99 | L15: 99 | M15: 99
A16: Number of Educators | B16: 0 | C16: 0 | D16: 0 | E16: 0 | F16: 0 | G16: 0 | H16: 3 | I16: 4 | J16: 5 | K16: 7 | L16: 9 | M16: 15
A17: PD Offerings Subscription Fee (Monthly Recurring) | B17: 150 | C17: 150 | D17: 150 | E17: 150 | F17: 150 | G17: 150 | H17: 150 | I17: 150 | J17: 150 | K17: 150 | L17: 150 | M17: 150
A18: Number of Educators | B18: 0 | C18: 0 | D18: 0 | E18: 0 | F18: =F16/2 -> 0 | G18: =G16/2 -> 0 | H18: =H16/2 -> 1.5 | I18: =I16/2 -> 2 | J18: =J16/2 -> 2.5 | K18: =K16/2 -> 3.5 | L18: =L16/2 -> 4.5 | M18: =M16/2 -> 7.5 | N18: Enrollment for PD courses is an estimate
A19: Total Add On Fees | B19: =SUM(PRODUCT(B15,B16),PRODUCT(B17,B18)) -> 0 | C19: =SUM(PRODUCT(C15,C16),PRODUCT(C17,C18)) -> 0 | D19: =SUM(PRODUCT(D15,D16),PRODUCT(D17,D18)) -> 0 | E19: =SUM(PRODUCT(E15,E16),PRODUCT(E17,E18)) -> 0 | F19: =SUM(PRODUCT(F15,F16),PRODUCT(F17,F18)) -> 0 | G19: =SUM(PRODUCT(G15,G16),PRODUCT(G17,G18)) -> 0 | H19: =SUM(PRODUCT(H15,H16),PRODUCT(H17,H18)) -> 522 | I19: =SUM(PRODUCT(I15,I16),PRODUCT(I17,I18)) -> 696 | ... M19: =SUM(PRODUCT(M15,M16),PRODUCT(M17,M18)) -> 2610
A20: Basic Package Total Revenue | B20: =SUM(B19,B13) -> 1200 | C20: =SUM(C19,C13) -> 1200 | D20: =SUM(D19,D13) -> 1425 | E20: =SUM(E19,E13) -> 1650 | F20: =SUM(F19,F13) -> 1762.5 | G20: =SUM(G19,G13) -> 1875 | H20: =SUM(H19,H13) -> 2622 | I20: =SUM(I19,I13) -> 3246 | ... M20: =SUM(M19,M13) -> 7410
A22: School Package Subscription (Volume &/or Long Term Contract Fee Discount)
A23: Annual Base Fee ($5000 Annually) | B23: 1250 | C23: 1250 | D23: 1250 | E23: 1250 | F23: 1250 | G23: 1250 | H23: 1250 | I23: 1250 | J23: 1250 | K23: 1100 | L23: 1100 | M23: 1100
A24: IEP Access Fee Per Student | B24: 12 | C24: 12 | D24: 12 | E24: 12 | F24: 12 | G24: 12 | H24: 12 | I24: 12 | J24: 12 | K24: 12 | L24: 12 | M24: 12
A25: Number of Students | B25: 20 | C25: =ROUND(B25*(1-'Key Assumptions'!C16)+0,0) -> 19 | D25: =ROUND(C25*(1-'Key Assumptions'!C16)+0,0) -> 18 | E25: =ROUND(D25*(1-'Key Assumptions'!C16)+20,0) -> 37 | F25: =ROUND(E25*(1-'Key Assumptions'!C16)+20,0) -> 55 | G25: =ROUND(F25*(1-'Key Assumptions'!C16)+20,0) -> 72 | H25: =ROUND(G25*(1-'Key Assumptions'!C16)+20,0) -> 88 | I25: =ROUND(H25*(1-'Key Assumptions'!C16)+20,0) -> 104 | J25: =ROUND(I25*(1-'Key Assumptions'!C16)+40,0) -> 139 | K25: =ROUND(J25*(1-'Key Assumptions'!C16)+40,0) -> 172 | L25: =ROUND(K25*(1-'Key Assumptions'!C16)+60,0) -> 223 | M25: =ROUND(L25*(1-'Key Assumptions'!C16)+80,0) -> 292
A26: AI Tool Pricing Per Student | B26: 12 | C26: 12 | D26: 12 | E26: 12 | F26: 12 | G26: 12 | H26: 12 | I26: 12 | J26: 12 | K26: 11 | L26: 11 | M26: 11
A27: Total IEP Fees | B27: =SUM(B23,(PRODUCT(B24,B25)),(PRODUCT(B25,B26))) -> 1730 | C27: =SUM(C23,(PRODUCT(C24,C25)),(PRODUCT(C25,C26))) -> 1706 | D27: =SUM(D23,(PRODUCT(D24,D25)),(PRODUCT(D25,D26))) -> 1682 | E27: =SUM(E23,(PRODUCT(E24,E25)),(PRODUCT(E25,E26))) -> 2138 | F27: =SUM(F23,(PRODUCT(F24,F25)),(PRODUCT(F25,F26))) -> 2570 | G27: =SUM(G23,(PRODUCT(G24,G25)),(PRODUCT(G25,G26))) -> 2978 | H27: =SUM(H23,(PRODUCT(H24,H25)),(PRODUCT(H25,H26))) -> 3362 | I27: =SUM(I23,(PRODUCT(I24,I25)),(PRODUCT(I25,I26))) -> 3746 | ... M27: =SUM(M23,(PRODUCT(M24,M25)),(PRODUCT(M25,M26))) -> 7816
A28: Additional Add-ons: Data Migration, Strategy Library, PD Offerings
A29: Strategy Library Subscription Fee (Incl. In Software Access) | B29: 0 | C29: 0 | D29: 0 | E29: 0 | F29: 0 | G29: 0 | H29: 0 | I29: 0 | J29: 0 | K29: 0 | L29: 0 | M29: 0
A30: PD Offerings Subscription Fee (Monthly Recurring) | B30: 150 | C30: 150 | D30: 150 | E30: 150 | F30: 150 | G30: 150 | H30: 150 | I30: 150 | J30: 150 | K30: 150 | L30: 150 | M30: 150
A31: PD Offerings Subscription Fee (Monthly Recurring) | B31: 0 | C31: 0 | D31: 0 | E31: 0 | F31: 0 | G31: 0 | H31: 3 | I31: 4 | J31: 5 | K31: 7 | L31: 9 | M31: 15
A32: Total Add On Fees | B32: =PRODUCT(B30,B31) -> 0 | C32: =PRODUCT(C30,C31) -> 0 | D32: =PRODUCT(D30,D31) -> 0 | E32: =PRODUCT(E30,E31) -> 0 | F32: =PRODUCT(F30,F31) -> 0 | G32: =PRODUCT(G30,G31) -> 0 | H32: =PRODUCT(H30,H31) -> 450 | I32: =PRODUCT(I30,I31) -> 600 | ... M32: =PRODUCT(M30,M31) -> 2250
A33: School Package Total Revenue | B33: =SUM(B32+B27) -> 1730 | C33: =SUM(C32+C27) -> 1706 | D33: =SUM(D32+D27) -> 1682 | E33: =SUM(E32+E27) -> 2138 | F33: =SUM(F32+F27) -> 2570 | G33: =SUM(G32+G27) -> 2978 | H33: =SUM(H32+H27) -> 3812 | I33: =SUM(I32+I27) -> 4346 | ... M33: =SUM(M32+M27) -> 10066
A35: Custom Package (Bespoke Fee / Long Term Contract Fee Discount)
A36: Annual Base Fee ($20000 Annually) | B36: 0 | C36: 0 | D36: 0 | E36: 0 | F36: 0 | G36: 5000 | H36: 5000 | I36: 5000 | J36: 5000 | K36: 10000 | L36: 10000 | M36: 10000 | N36: Cost calculated through salary of software devs, in India.
A37: IEP Access Fee Per Student | B37: 0 | C37: 0 | D37: 0 | E37: 0 | F37: 0 | G37: 12 | H37: 12 | I37: 12 | J37: 12 | K37: 12 | L37: 12 | M37: 12
A38: Number of Students | B38: 0 | C38: 0 | D38: 0 | E38: 0 | F38: 0 | G38: 30 | H38: =ROUND(G38*(1-'Key Assumptions'!C16)+0,0) -> 29 | I38: =ROUND(H38*(1-'Key Assumptions'!C16)+0,0) -> 28 | J38: =ROUND(I38*(1-'Key Assumptions'!C16)+30,0) -> 57 | K38: =ROUND(J38*(1-'Key Assumptions'!C16)+30,0) -> 84 | L38: =ROUND(K38*(1-'Key Assumptions'!C16)+0,0) -> 80 | M38: =ROUND(L38*(1-'Key Assumptions'!C16)+0,0) -> 76
A39: AI Tool Pricing Per Student | B39: 0 | C39: 0 | D39: 0 | E39: 0 | F39: 0 | G39: 10 | H39: 10 | I39: 10 | J39: 10 | K39: 9 | L39: 9 | M39: 9
A40: Total IEP Fees | B40: 0 | C40: 0 | D40: 0 | E40: 0 | F40: 0 | G40: =SUM(G36,PRODUCT(G37,G38),PRODUCT(G38,G39)) -> 5660 | H40: =SUM(H36,PRODUCT(H37,H38),PRODUCT(H38,H39)) -> 5638 | I40: =SUM(I36,PRODUCT(I37,I38),PRODUCT(I38,I39)) -> 5616 | J40: =SUM(J36,PRODUCT(J37,J38),PRODUCT(J38,J39)) -> 6254 | K40: =SUM(K36,PRODUCT(K37,K38),PRODUCT(K38,K39)) -> 11764 | L40: =SUM(L36,PRODUCT(L37,L38),PRODUCT(L38,L39)) -> 11680 | M40: =SUM(M36,PRODUCT(M37,M38),PRODUCT(M38,M39)) -> 11596
A41: Additional Add-ons: Data Migration, Strategy Library, PD Offerings
A42: Strategy Library Subscription Fee (Incl. In Software Access) | B42: 0 | C42: 0 | D42: 0 | E42: 0 | F42: 0 | G42: 0 | H42: 0 | I42: 0 | J42: 0 | K42: 0 | L42: 0 | M42: 0
A43: PD Offerings Subscription Fee (Monthly Recurring) | B43: 100 | C43: 100 | D43: 100 | E43: 100 | F43: 100 | G43: 100 | H43: 100 | I43: 100 | J43: 100 | K43: 100 | L43: 100 | M43: 100
...

Sheet Unit Economics
A1: IEPPAL — UNIT ECONOMICS
B3: YEAR 1 | F3: YEAR 2 | J3: YEAR 3
B4: Q1 | C4: Q2 | D4: Q3 | E4: Q4 | F4: Q1 | G4: Q2 | H4: Q3 | I4: Q4 | J4: Q1 | K4: Q2 | L4: Q3 | M4: Q4
A5: CAC per Quarter | B5: =IF('Income Statement'!B106=0,"-",IFERROR('Income Statement'!B106/('Income Statement'!B10+'Income Statement'!B25+'Income Statement'!B38),"-")) -> - | C5: =IFERROR('Income Statement'!C106/(MAX('Income Statement'!C10-'Income Statement'!B10,0)+MAX('Income Statement'!C25-'Income Statement'!B25,0)+MAX('Income Statement'!C38-'Income Statement'!B38,0)),"-") -> - | D5: =IFERROR('Income Statement'!D106/(MAX('Income Statement'!D10-'Income Statement'!C10,0)+MAX('Income Statement'!D25-'Income Statement'!C25,0)+MAX('Income Statement'!D38-'Income Statement'!C38,0)),"-") -> 0 | E5: =IFERROR('Income Statement'!E106/(MAX('Income Statement'!E10-'Income Statement'!D10,0)+MAX('Income Statement'!E25-'Income Statement'!D25,0)+MAX('Income Statement'!E38-'Income Statement'!D38,0)),"-") -> 34.482759 | F5: =IFERROR('Income Statement'!F106/(MAX('Income Statement'!F10-'Income Statement'!E10,0)+MAX('Income Statement'!F25-'Income Statement'!E25,0)+MAX('Income Statement'!F38-'Income Statement'!E38,0)),"-") -> 43.478261 | G5: =IFERROR('Income Statement'!G106/(MAX('Income Statement'!G10-'Income Statement'!F10,0)+MAX('Income Statement'!G25-'Income Statement'!F25,0)+MAX('Income Statement'!G38-'Income Statement'!F38,0)),"-") -> 38.461538 | H5: =IFERROR('Income Statement'!H106/(MAX('Income Statement'!H10-'Income Statement'!G10,0)+MAX('Income Statement'!H25-'Income Statement'!G25,0)+MAX('Income Statement'!H38-'Income Statement'!G38,0)),"-") -> 375 | I5: =IFERROR('Income Statement'!I106/(MAX('Income Statement'!I10-'Income Statement'!H10,0)+MAX('Income Statement'!I25-'Income Statement'!H25,0)+MAX('Income Statement'!I38-'Income Statement'!H38,0)),"-") -> 159.72222 | J5: =IFERROR('Income Statement'!J106/(MAX('Income Statement'!J10-'Income Statement'!I10,0)+MAX('Income Statement'!J25-'Income Statement'!I25,0)+MAX('Income Statement'!J38-'Income Statement'!I38,0)),"-") -> 163.69048 | ... M5: =IFERROR('Income Statement'!M106/(MAX('Income Statement'!M10-'Income Statement'!L10,0)+MAX('Income Statement'!M25-'Income Statement'!L25,0)+MAX('Income Statement'!M38-'Income Statement'!L38,0)),"-") -> 154.49438
A6: CAC Annually | E6: =IFERROR(SUM('Income Statement'!B106:'Income Statement'!E106)/(('Income Statement'!B10+'Income Statement'!B25+'Income Statement'!B38)+MAX('Income Statement'!C10-'Income Statement'!B10,0)+MAX('Income Statement'!C25-'Income Statement'!B25,0)+MAX('Income Statement'!C38-'Income Statement'!B38,0)+MAX('Income Statement'!D10-'Income Statement'!C10,0)+MAX('Income Statement'!D25-'Income Statement'!C25,0)+MAX('Income Statement'!D38-'Income Statement'!C38,0)+MAX('Income Statement'!E10-'Income Statement'!D10,0)+MAX('Income Statement'!E25-'Income Statement'!D25,0)+MAX('Income Statement'!E38-'Income Statement'!D38,0)),"-") -> 12.658228 | I6: =IFERROR(SUM('Income Statement'!F106:'Income Statement'!I106)/(MAX('Income Statement'!F10-'Income Statement'!E10,0)+MAX('Income Statement'!F25-'Income Statement'!E25,0)+MAX('Income Statement'!F38-'Income Statement'!E38,0)+MAX('Income Statement'!G10-'Income Statement'!F10,0)+MAX('Income Statement'!G25-'Income Statement'!F25,0)+MAX('Income Statement'!G38-'Income Statement'!F38,0)+MAX('Income Statement'!H10-'Income Statement'!G10,0)+MAX('Income Statement'!H25-'Income Statement'!G25,0)+MAX('Income Statement'!H38-'Income Statement'!G38,0)+MAX('Income Statement'!I10-'Income Statement'!H10,0)+MAX('Income Statement'!I25-'Income Statement'!H25,0)+MAX('Income Statement'!I38-'Income Statement'!H38,0)),"-") -> 135.0365 | M6: =IFERROR(SUM('Income Statement'!J106:'Income Statement'!M106)/(MAX('Income Statement'!J10-'Income Statement'!I10,0)+MAX('Income Statement'!J25-'Income Statement'!I25,0)+MAX('Income Statement'!J38-'Income Statement'!I38,0)+MAX('Income Statement'!K10-'Income Statement'!J10,0)+MAX('Income Statement'!K25-'Income Statement'!J25,0)+MAX('Income Statement'!K38-'Income Statement'!J38,0)+MAX('Income Statement'!L10-'Income Statement'!K10,0)+MAX('Income Statement'!L25-'Income Statement'!K25,0)+MAX('Income Statement'!L38-'Income Statement'!K38,0)+MAX('Income Statement'!M10-'Income Statement'!L10,0)+MAX('Income Statement'!M25-'Income Statement'!L25,0)+MAX('Income Statement'!M38-'Income Statement'!L38,0)),"-") -> 180.23256
A7: Variable COGS per Student (AWS+AI Tool, all tiers blended) | B7: =IFERROR('Income Statement'!B96/('Income Statement'!B9+'Income Statement'!B25+'Income Statement'!B38),0) -> 2.4397714 | C7: =IFERROR('Income Statement'!C96/('Income Statement'!C9+'Income Statement'!C25+'Income Statement'!C38),0) -> 2.6927529 | D7: =IFERROR('Income Statement'!D96/('Income Statement'!D9+'Income Statement'!D25+'Income Statement'!D38),0) -> 3.6529455 | E7: =IFERROR('Income Statement'!E96/('Income Statement'!E9+'Income Statement'!E25+'Income Statement'!E38),0) -> 3.5059385 | F7: =IFERROR('Income Statement'!F96/('Income Statement'!F9+'Income Statement'!F25+'Income Statement'!F38),0) -> 3.4439429 | G7: =IFERROR('Income Statement'!G96/('Income Statement'!G9+'Income Statement'!G25+'Income Statement'!G38),0) -> 3.358947 | H7: =IFERROR('Income Statement'!H96/('Income Statement'!H9+'Income Statement'!H25+'Income Statement'!H38),0) -> 4.4050364 | I7: =IFERROR('Income Statement'!I96/('Income Statement'!I9+'Income Statement'!I25+'Income Statement'!I38),0) -> 5.6015293 | ... M7: =IFERROR('Income Statement'!M96/('Income Statement'!M9+'Income Statement'!M25+'Income Statement'!M38),0) -> 8.4479561
A8: Basic Tier: Revenue per Student | B8: =IFERROR('Income Statement'!B20/'Income Statement'!B9,0) -> 80 | C8: =IFERROR('Income Statement'!C20/'Income Statement'!C9,0) -> 80 | D8: =IFERROR('Income Statement'!D20/'Income Statement'!D9,0) -> 95 | E8: =IFERROR('Income Statement'!E20/'Income Statement'!E9,0) -> 110 | F8: =IFERROR('Income Statement'!F20/'Income Statement'!F9,0) -> 117.5 | G8: =IFERROR('Income Statement'!G20/'Income Statement'!G9,0) -> 125 | H8: =IFERROR('Income Statement'!H20/'Income Statement'!H9,0) -> 174.8 | I8: =IFERROR('Income Statement'!I20/'Income Statement'!I9,0) -> 216.4 | ... M8: =IFERROR('Income Statement'!M20/'Income Statement'!M9,0) -> 494
A9: Schools Tier: Revenue per Student | B9: =IFERROR('Income Statement'!B33/'Income Statement'!B25,0) -> 86.5 | C9: =IFERROR('Income Statement'!C33/'Income Statement'!C25,0) -> 89.789474 | D9: =IFERROR('Income Statement'!D33/'Income Statement'!D25,0) -> 93.444444 | E9: =IFERROR('Income Statement'!E33/'Income Statement'!E25,0) -> 57.783784 | F9: =IFERROR('Income Statement'!F33/'Income Statement'!F25,0) -> 46.727273 | G9: =IFERROR('Income Statement'!G33/'Income Statement'!G25,0) -> 41.361111 | H9: =IFERROR('Income Statement'!H33/'Income Statement'!H25,0) -> 43.318182 | I9: =IFERROR('Income Statement'!I33/'Income Statement'!I25,0) -> 41.788462 | ... M9: =IFERROR('Income Statement'!M33/'Income Statement'!M25,0) -> 34.472603
A10: Custom Tier: Revenue per Student | B10: =IFERROR('Income Statement'!B50/'Income Statement'!B38,0) -> 0 | C10: =IFERROR('Income Statement'!C50/'Income Statement'!C38,0) -> 0 | D10: =IFERROR('Income Statement'!D50/'Income Statement'!D38,0) -> 0 | E10: =IFERROR('Income Statement'!E50/'Income Statement'!E38,0) -> 0 | F10: =IFERROR('Income Statement'!F50/'Income Statement'!F38,0) -> 0 | G10: =IFERROR('Income Statement'!G50/'Income Statement'!G38,0) -> 372 | H10: =IFERROR('Income Statement'!H50/'Income Statement'!H38,0) -> 411.65517 | I10: =IFERROR('Income Statement'!I50/'Income Statement'!I38,0) -> 454.14286 | ... M10: =IFERROR('Income Statement'!M50/'Income Statement'!M38,0) -> 349.94737
A11: Variable Margin per Student — Basic (Rev - VarCOGS) | B11: =B8-B7 -> 77.560229 | C11: =C8-C7 -> 77.307247 | D11: =D8-D7 -> 91.347055 | E11: =E8-E7 -> 106.49406 | F11: =F8-F7 -> 114.05606 | G11: =G8-G7 -> 121.64105 | H11: =H8-H7 -> 170.39496 | I11: =I8-I7 -> 210.79847 | ... M11: =M8-M7 -> 485.55204
A12: Variable Margin per Student — Schools | B12: =B9-B7 -> 84.060229 | C12: =C9-C7 -> 87.096721 | D12: =D9-D7 -> 89.791499 | E12: =E9-E7 -> 54.277845 | F12: =F9-F7 -> 43.28333 | G12: =G9-G7 -> 38.002164 | H12: =H9-H7 -> 38.913145 | I12: =I9-I7 -> 36.186932 | ... M12: =M9-M7 -> 26.024647
A13: Variable Margin per Student — Custom | B13: =IF('Income Statement'!B38=0,"-",B10-B7) -> - | C13: =IF('Income Statement'!C38=0,"-",C10-C7) -> - | D13: =IF('Income Statement'!D38=0,"-",D10-D7) -> - | E13: =IF('Income Statement'!E38=0,"-",E10-E7) -> - | F13: =IF('Income Statement'!F38=0,"-",F10-F7) -> - | G13: =IF('Income Statement'!G38=0,"-",G10-G7) -> 368.64105 | H13: =IF('Income Statement'!H38=0,"-",H10-H7) -> 407.25014 | I13: =IF('Income Statement'!I38=0,"-",I10-I7) -> 448.54133 | ... M13: =IF('Income Statement'!M38=0,"-",M10-M7) -> 341.49941
A14: LTV — Basic (VarMargin ÷ Quarterly Churn Rate) | B14: =IFERROR(B11/'Key Assumptions'!C16,0) -> 1551.2046 | C14: =IFERROR(C11/'Key Assumptions'!C16,0) -> 1546.1449 | D14: =IFERROR(D11/'Key Assumptions'!C16,0) -> 1826.9411 | E14: =IFERROR(E11/'Key Assumptions'!C16,0) -> 2129.8812 | F14: =IFERROR(F11/'Key Assumptions'!C16,0) -> 2281.1211 | G14: =IFERROR(G11/'Key Assumptions'!C16,0) -> 2432.8211 | H14: =IFERROR(H11/'Key Assumptions'!C16,0) -> 3407.8993 | I14: =IFERROR(I11/'Key Assumptions'!C16,0) -> 4215.9694 | J14: =IFERROR(J11/'Key Assumptions'!C16,0) -> 5042.824 | K14: =IFERROR(K11/'Key Assumptions'!C16,0) -> 6089.6019 | L14: =IFERROR(L11/'Key Assumptions'!C16,0) -> 7729.6549 | M14: =IFERROR(M11/'Key Assumptions'!C16,0) -> 9711.0409
A15: LTV — Schools | B15: =IFERROR(B12/'Key Assumptions'!C16,0) -> 1681.2046 | C15: =IFERROR(C12/'Key Assumptions'!C16,0) -> 1741.9344 | D15: =IFERROR(D12/'Key Assumptions'!C16,0) -> 1795.83 | E15: =IFERROR(E12/'Key Assumptions'!C16,0) -> 1085.5569 | F15: =IFERROR(F12/'Key Assumptions'!C16,0) -> 865.6666 | G15: =IFERROR(G12/'Key Assumptions'!C16,0) -> 760.04328 | H15: =IFERROR(H12/'Key Assumptions'!C16,0) -> 778.26291 | I15: =IFERROR(I12/'Key Assumptions'!C16,0) -> 723.73865 | J15: =IFERROR(J12/'Key Assumptions'!C16,0) -> 650.59382 | K15: =IFERROR(K12/'Key Assumptions'!C16,0) -> 575.60189 | L15: =IFERROR(L12/'Key Assumptions'!C16,0) -> 521.38583 | M15: =IFERROR(M12/'Key Assumptions'!C16,0) -> 520.49293
A16: LTV — Custom | B16: =IF('Income Statement'!B38=0,"-",IFERROR(B13/'Key Assumptions'!C16,"-")) -> - | C16: =IF('Income Statement'!C38=0,"-",IFERROR(C13/'Key Assumptions'!C16,"-")) -> - | D16: =IF('Income Statement'!D38=0,"-",IFERROR(D13/'Key Assumptions'!C16,"-")) -> - | E16: =IF('Income Statement'!E38=0,"-",IFERROR(E13/'Key Assumptions'!C16,"-")) -> - | F16: =IF('Income Statement'!F38=0,"-",IFERROR(F13/'Key Assumptions'!C16,"-")) -> - | G16: =IF('Income Statement'!G38=0,"-",IFERROR(G13/'Key Assumptions'!C16,"-")) -> 7372.8211 | H16: =IF('Income Statement'!H38=0,"-",IFERROR(H13/'Key Assumptions'!C16,"-")) -> 8145.0027 | I16: =IF('Income Statement'!I38=0,"-",IFERROR(I13/'Key Assumptions'!C16,"-")) -> 8970.8266 | J16: =IF('Income Statement'!J38=0,"-",IFERROR(J13/'Key Assumptions'!C16,"-")) -> 4849.1398 | K16: =IF('Income Statement'!K38=0,"-",IFERROR(K13/'Key Assumptions'!C16,"-")) -> 5857.0305 | L16: =IF('Income Statement'!L38=0,"-",IFERROR(L13/'Key Assumptions'!C16,"-")) -> 6311.6549 | M16: =IF('Income Statement'!M38=0,"-",IFERROR(M13/'Key Assumptions'!C16,"-")) -> 6829.9882
A17: LTV:CAC — Basic | B17: =IFERROR(B14/B5,"-") -> - | C17: =IFERROR(C14/C5,"-") -> - | D17: =IFERROR(D14/D5,"-") -> - | E17: =IFERROR(E14/E5,"-") -> 61.766556 | F17: =IFERROR(F14/F5,"-") -> 52.465786 | G17: =IFERROR(G14/G5,"-") -> 63.253348 | H17: =IFERROR(H14/H5,"-") -> 9.0877314 | I17: =IFERROR(I14/I5,"-") -> 26.395635 | ... M17: =IFERROR(M14/M5,"-") -> 62.856919
A18: LTV:CAC — Schools | B18: =IFERROR(B15/B5,"-") -> - | C18: =IFERROR(C15/C5,"-") -> - | D18: =IFERROR(D15/D5,"-") -> - | E18: =IFERROR(E15/E5,"-") -> 31.48115 | F18: =IFERROR(F15/F5,"-") -> 19.910332 | G18: =IFERROR(G15/G5,"-") -> 19.761125 | H18: =IFERROR(H15/H5,"-") -> 2.0753678 | I18: =IFERROR(I15/I5,"-") -> 4.5312333 | ... M18: =IFERROR(M15/M5,"-") -> 3.3690088
A19: LTV:CAC — Custom | B19: =IF(B16="-","-",IF(B5="-","-",IFERROR(B16/B5,"-"))) -> - | C19: =IF(C16="-","-",IF(C5="-","-",IFERROR(C16/C5,"-"))) -> - | D19: =IF(D16="-","-",IF(D5="-","-",IFERROR(D16/D5,"-"))) -> - | E19: =IF(E16="-","-",IF(E5="-","-",IFERROR(E16/E5,"-"))) -> - | F19: =IF(F16="-","-",IF(F5="-","-",IFERROR(F16/F5,"-"))) -> - | G19: =IF(G16="-","-",IF(G5="-","-",IFERROR(G16/G5,"-"))) -> 191.69335 | H19: =IF(H16="-","-",IF(H5="-","-",IFERROR(H16/H5,"-"))) -> 21.720007 | I19: =IF(I16="-","-",IF(I5="-","-",IFERROR(I16/I5,"-"))) -> 56.165175 | ... M19: =IF(M16="-","-",IF(M5="-","-",IFERROR(M16/M5,"-"))) -> 44.208651
A20: CAC per Account (S&M ÷ New School Accounts Won) | B20: =IF('Income Statement'!B106=0,"-",IFERROR('Income Statement'!B106/('Account Waterfall'!B7+'Account Waterfall'!B12+'Account Waterfall'!B17),"-")) -> - | C20: =IF('Income Statement'!C106=0,"-",IFERROR('Income Statement'!C106/('Account Waterfall'!C7+'Account Waterfall'!C12+'Account Waterfall'!C17),"-")) -> - | D20: =IF('Income Statement'!D106=0,"-",IFERROR('Income Statement'!D106/('Account Waterfall'!D7+'Account Waterfall'!D12+'Account Waterfall'!D17),"-")) -> - | E20: =IF('Income Statement'!E106=0,"-",IFERROR('Income Statement'!E106/('Account Waterfall'!E7+'Account Waterfall'!E12+'Account Waterfall'!E17),"-")) -> 500 | F20: =IF('Income Statement'!F106=0,"-",IFERROR('Income Statement'!F106/('Account Waterfall'!F7+'Account Waterfall'!F12+'Account Waterfall'!F17),"-")) -> 500 | G20: =IF('Income Statement'!G106=0,"-",IFERROR('Income Statement'!G106/('Account Waterfall'!G7+'Account Waterfall'!G12+'Account Waterfall'!G17),"-")) -> 666.66667 | H20: =IF('Income Statement'!H106=0,"-",IFERROR('Income Statement'!H106/('Account Waterfall'!H7+'Account Waterfall'!H12+'Account Waterfall'!H17),"-")) -> 4875 | I20: =IF('Income Statement'!I106=0,"-",IFERROR('Income Statement'!I106/('Account Waterfall'!I7+'Account Waterfall'!I12+'Account Waterfall'!I17),"-")) -> 1916.6667 | ... M20: =IF('Income Statement'!M106=0,"-",IFERROR('Income Statement'!M106/('Account Waterfall'!M7+'Account Waterfall'!M12+'Account Waterfall'!M17),"-")) -> 2291.6667
A22: PAYBACK, RETENTION & CONTRACT METRICS
A23: Gross Margin % (variable COGS only) | B23: =IFERROR(1-'Income Statement'!B96/'Income Statement'!B52,0) -> 0.97085597 | C23: =IFERROR(1-'Income Statement'!C96/'Income Statement'!C52,0) -> 0.96849498 | D23: =IFERROR(1-'Income Statement'!D96/'Income Statement'!D52,0) -> 0.96120142 | E23: =IFERROR(1-'Income Statement'!E96/'Income Statement'!E52,0) -> 0.95187202 | F23: =IFERROR(1-'Income Statement'!F96/'Income Statement'!F52,0) -> 0.94435638 | G23: =IFERROR(1-'Income Statement'!G96/'Income Statement'!G52,0) -> 0.97545764 | H23: =IFERROR(1-'Income Statement'!H96/'Income Statement'!H52,0) -> 0.96835049 | I23: =IFERROR(1-'Income Statement'!I96/'Income Statement'!I52,0) -> 0.95945318 | ... M23: =IFERROR(1-'Income Statement'!M96/'Income Statement'!M52,0) -> 0.92658452
A24: ARPA per month (Qtrly Revenue ÷ Total Accts ÷ 3) | B24: =IFERROR('Income Statement'!B52/(('Account Waterfall'!B9+'Account Waterfall'!B14+'Account Waterfall'!B19)/3),"-") -> 4395 | C24: =IFERROR('Income Statement'!C52/(('Account Waterfall'!C9+'Account Waterfall'!C14+'Account Waterfall'!C19)/3),"-") -> 4359 | D24: =IFERROR('Income Statement'!D52/(('Account Waterfall'!D9+'Account Waterfall'!D14+'Account Waterfall'!D19)/3),"-") -> 3107 | E24: =IFERROR('Income Statement'!E52/(('Account Waterfall'!E9+'Account Waterfall'!E14+'Account Waterfall'!E19)/3),"-") -> 2272.8 | F24: =IFERROR('Income Statement'!F52/(('Account Waterfall'!F9+'Account Waterfall'!F14+'Account Waterfall'!F19)/3),"-") -> 1856.7857 | G24: =IFERROR('Income Statement'!G52/(('Account Waterfall'!G9+'Account Waterfall'!G14+'Account Waterfall'!G19)/3),"-") -> 4803.9 | H24: =IFERROR('Income Statement'!H52/(('Account Waterfall'!H9+'Account Waterfall'!H14+'Account Waterfall'!H19)/3),"-") -> 4593 | I24: =IFERROR('Income Statement'!I52/(('Account Waterfall'!I9+'Account Waterfall'!I14+'Account Waterfall'!I19)/3),"-") -> 4061.6 | ... M24: =IFERROR('Income Statement'!M52/(('Account Waterfall'!M9+'Account Waterfall'!M14+'Account Waterfall'!M19)/3),"-") -> 4131.75
A25: CAC Payback Period — months (CAC per Account ÷ Monthly Gross Profit per Account) | B25: =IF(B20="-","-",IF(B24="-","-",IFERROR(B20/(B24*B23),"-"))) -> - | C25: =IF(C20="-","-",IF(C24="-","-",IFERROR(C20/(C24*C23),"-"))) -> - | D25: =IF(D20="-","-",IF(D24="-","-",IFERROR(D20/(D24*D23),"-"))) -> - | E25: =IF(E20="-","-",IF(E24="-","-",IFERROR(E20/(E24*E23),"-"))) -> 0.23111611 | F25: =IF(F20="-","-",IF(F24="-","-",IFERROR(F20/(F24*F23),"-"))) -> 0.28514929 | G25: =IF(G20="-","-",IF(G24="-","-",IFERROR(G20/(G24*G23),"-"))) -> 0.14226772 | H25: =IF(H20="-","-",IF(H24="-","-",IFERROR(H20/(H24*H23),"-"))) -> 1.0960884 | I25: =IF(I20="-","-",IF(I24="-","-",IFERROR(I20/(I24*I23),"-"))) -> 0.49184205 | ... M25: =IF(M20="-","-",IF(M24="-","-",IFERROR(M20/(M24*M23),"-"))) -> 0.59859402
A27: Net Revenue Retention — NRR | B27: =IFERROR('ARR Waterfall'!B27,"-") -> - | C27: =IFERROR('ARR Waterfall'!C27,"-") -> 1.0124126 | D27: =IFERROR('ARR Waterfall'!D27,"-") -> 1.0107922 | E27: =IFERROR('ARR Waterfall'!E27,"-") -> 0.99317313 | F27: =IFERROR('ARR Waterfall'!F27,"-") -> 0.98219288 | G27: =IFERROR('ARR Waterfall'!G27,"-") -> 0.97764977 | H27: =IFERROR('ARR Waterfall'!H27,"-") -> 1.0271926 | I27: =IFERROR('ARR Waterfall'!I27,"-") -> 1.0229669 | ... M27: =IFERROR('ARR Waterfall'!M27,"-") -> 1.0064419
A28: Quarterly Gross Churn Rate (assumption) | B28: ='Key Assumptions'!C16 -> 0.05 | C28: ='Key Assumptions'!C16 -> 0.05 | D28: ='Key Assumptions'!C16 -> 0.05 | E28: ='Key Assumptions'!C16 -> 0.05 | F28: ='Key Assumptions'!C16 -> 0.05 | G28: ='Key Assumptions'!C16 -> 0.05 | H28: ='Key Assumptions'!C16 -> 0.05 | I28: ='Key Assumptions'!C16 -> 0.05 | J28: ='Key Assumptions'!C16 -> 0.05 | K28: ='Key Assumptions'!C16 -> 0.05 | L28: ='Key Assumptions'!C16 -> 0.05 | M28: ='Key Assumptions'!C16 -> 0.05
A30: ACV per School — Basic (Quarterly ARR ÷ Active Accounts) | B30: =IFERROR('ARR Waterfall'!B6/'Account Waterfall'!B9,"-") -> 4800 | C30: =IFERROR('ARR Waterfall'!C6/'Account Waterfall'!C9,"-") -> 4800 | D30: =IFERROR('ARR Waterfall'!D6/'Account Waterfall'!D9,"-") -> 2850 | E30: =IFERROR('ARR Waterfall'!E6/'Account Waterfall'!E9,"-") -> 2200 | F30: =IFERROR('ARR Waterfall'!F6/'Account Waterfall'!F9,"-") -> 1762.5 | G30: =IFERROR('ARR Waterfall'!G6/'Account Waterfall'!G9,"-") -> 1500 | H30: =IFERROR('ARR Waterfall'!H6/'Account Waterfall'!H9,"-") -> 1748 | I30: =IFERROR('ARR Waterfall'!I6/'Account Waterfall'!I9,"-") -> 1623 | ... M30: =IFERROR('ARR Waterfall'!M6/'Account Waterfall'!M9,"-") -> 2117.1429
A31: ACV per School — Schools | B31: =IFERROR('ARR Waterfall'!B7/'Account Waterfall'!B14,"-") -> 6920 | C31: =IFERROR('ARR Waterfall'!C7/'Account Waterfall'!C14,"-") -> 6824 | D31: =IFERROR('ARR Waterfall'!D7/'Account Waterfall'!D14,"-") -> 6728 | E31: =IFERROR('ARR Waterfall'!E7/'Account Waterfall'!E14,"-") -> 4276 | F31: =IFERROR('ARR Waterfall'!F7/'Account Waterfall'!F14,"-") -> 3426.6667 | G31: =IFERROR('ARR Waterfall'!G7/'Account Waterfall'!G14,"-") -> 2978 | H31: =IFERROR('ARR Waterfall'!H7/'Account Waterfall'!H14,"-") -> 3049.6 | I31: =IFERROR('ARR Waterfall'!I7/'Account Waterfall'!I14,"-") -> 2897.3333 | ... M31: =IFERROR('ARR Waterfall'!M7/'Account Waterfall'!M14,"-") -> 2684.2667
A32: ACV per School — Custom | B32: =IFERROR('ARR Waterfall'!B8/'Account Waterfall'!B19,"-") -> - | C32: =IFERROR('ARR Waterfall'!C8/'Account Waterfall'!C19,"-") -> - | D32: =IFERROR('ARR Waterfall'!D8/'Account Waterfall'!D19,"-") -> - | E32: =IFERROR('ARR Waterfall'!E8/'Account Waterfall'!E19,"-") -> - | F32: =IFERROR('ARR Waterfall'!F8/'Account Waterfall'!F19,"-") -> - | G32: =IFERROR('ARR Waterfall'!G8/'Account Waterfall'!G19,"-") -> 44640 | H32: =IFERROR('ARR Waterfall'!H8/'Account Waterfall'!H19,"-") -> 47752 | I32: =IFERROR('ARR Waterfall'!I8/'Account Waterfall'!I19,"-") -> 50864 | ... M32: =IFERROR('ARR Waterfall'!M8/'Account Waterfall'!M19,"-") -> 35461.333
A34: Model Notes
A35: [1] LTV = Variable Margin per Student ÷ Quarterly Churn Rate. Fixed COGS (SE salary, security, GDPR) are period costs captured in the P&L, not allocated at unit level.
A36: [2] LTV:CAC is front-loaded: CAC is incurred upfront while LTV accrues over the customer lifetime. Low ratios in early quarters are expected in a B2B EdTech investment phase. Target >3x by Y2Q3.
A37: [3] Custom tier rows show "-" in periods with zero Custom students. Blended COGS applied against no revenue produces a meaningless negative margin; omitted to avoid misleading reads.
A38: [4] CAC Payback Period uses CAC per Account (row 20), not per student. This aligns the denominator (ARPA per school × GM%) to the same unit. Benchmark: 12–18 months EdTech B2B | <12 = best-in-class | >24 = review CAC efficiency.
A39: [5] NRR from ARR Waterfall. Target >100% from Y2 onward — indicates expansion revenue from existing schools exceeds gross churn losses, a strong product-market fit signal.
A40: [6] ACV (Annual Contract Value) = Quarterly ARR by tier ÷ Active accounts for that tier. Reflects current-quarter run-rate annualised; fluctuates as student counts change within contracts.

Sheet Balance Sheet
A1: IEPPAL — BALANCE SHEET
B2: YEAR 1 | F2: YEAR 2 | J2: YEAR 3
B3: Q1 | C3: Q2 | D3: Q3 | E3: Q4 | F3: Q1 | G3: Q2 | H3: Q3 | I3: Q4 | J3: Q1 | K3: Q2 | L3: Q3 | M3: Q4
A4: ASSETS
A5: CURRENT ASSETS
A6: Cash & Cash Equivalents | B6: ='Cash Flow'!B31 -> 169049.61 | C6: ='Cash Flow'!C31 -> 154458.05 | D6: ='Cash Flow'!D31 -> 163227.51 | E6: ='Cash Flow'!E31 -> 156415.2 | F6: ='Cash Flow'!F31 -> 139394.12 | G6: ='Cash Flow'!G31 -> 200631.13 | H6: ='Cash Flow'!H31 -> 177919.66 | I6: ='Cash Flow'!I31 -> 162256.24 | ... M6: ='Cash Flow'!M31 -> 142652.24
A7: Accounts Receivable (Net)
A8: Prepaid Expenses
A9: Other Current Assets
A10: Total Current Assets | B10: =B6+B7+B8+B9 -> 169049.61 | C10: =C6+C7+C8+C9 -> 154458.05 | D10: =D6+D7+D8+D9 -> 163227.51 | E10: =E6+E7+E8+E9 -> 156415.2 | F10: =F6+F7+F8+F9 -> 139394.12 | G10: =G6+G7+G8+G9 -> 200631.13 | H10: =H6+H7+H8+H9 -> 177919.66 | I10: =I6+I7+I8+I9 -> 162256.24 | ... M10: =M6+M7+M8+M9 -> 142652.24
A12: NON-CURRENT ASSETS
A13: Property, Plant & Equipment (Net)
A14: Intangible Assets — Capitalised Software
A15: Right-of-Use Assets
A16: Other Non-Current Assets
A17: Total Non-Current Assets | B17: =B13+B14+B15+B16 -> 0 | C17: =C13+C14+C15+C16 -> 0 | D17: =D13+D14+D15+D16 -> 0 | E17: =E13+E14+E15+E16 -> 0 | F17: =F13+F14+F15+F16 -> 0 | G17: =G13+G14+G15+G16 -> 0 | H17: =H13+H14+H15+H16 -> 0 | I17: =I13+I14+I15+I16 -> 0 | ... M17: =M13+M14+M15+M16 -> 0
A19: TOTAL ASSETS | B19: =B10+B17 -> 169049.61 | C19: =C10+C17 -> 154458.05 | D19: =D10+D17 -> 163227.51 | E19: =E10+E17 -> 156415.2 | F19: =F10+F17 -> 139394.12 | G19: =G10+G17 -> 200631.13 | H19: =H10+H17 -> 177919.66 | I19: =I10+I17 -> 162256.24 | ... M19: =M10+M17 -> 142652.24
A21: LIABILITIES
A22: CURRENT LIABILITIES
A23: Accounts Payable
A24: Deferred Revenue | B24: =MAX(0,B54) -> 5940 | C24: =MAX(0,C54) -> 3034 | D24: =MAX(0,D54) -> 3317 | E24: =MAX(0,E54) -> 8399 | F24: =MAX(0,F54) -> 12936.5 | G24: =MAX(0,G54) -> 26453.5 | H24: =MAX(0,H54) -> 16951.5 | I24: =MAX(0,I54) -> 8903.5 | ... M24: =MAX(0,M54) -> 0
A25: Accrued Expenses
A26: Income Tax Payable
A27: Other Current Liabilities
A28: Total Current Liabilities | B28: =B23+B24+B25+B26+B27 -> 5940 | C28: =C23+C24+C25+C26+C27 -> 3034 | D28: =D23+D24+D25+D26+D27 -> 3317 | E28: =E23+E24+E25+E26+E27 -> 8399 | F28: =F23+F24+F25+F26+F27 -> 12936.5 | G28: =G23+G24+G25+G26+G27 -> 26453.5 | H28: =H23+H24+H25+H26+H27 -> 16951.5 | I28: =I23+I24+I25+I26+I27 -> 8903.5 | ... M28: =M23+M24+M25+M26+M27 -> 0
A30: NON-CURRENT LIABILITIES
A31: Long-Term Debt
A32: Deferred Tax Liabilities
A33: Other Non-Current Liabilities
A34: Total Non-Current Liabilities | B34: =B31+B32+B33 -> 0 | C34: =C31+C32+C33 -> 0 | D34: =D31+D32+D33 -> 0 | E34: =E31+E32+E33 -> 0 | F34: =F31+F32+F33 -> 0 | G34: =G31+G32+G33 -> 0 | H34: =H31+H32+H33 -> 0 | I34: =I31+I32+I33 -> 0 | ... M34: =M31+M32+M33 -> 0
A36: TOTAL LIABILITIES | B36: =B28+B34 -> 5940 | C36: =C28+C34 -> 3034 | D36: =D28+D34 -> 3317 | E36: =E28+E34 -> 8399 | F36: =F28+F34 -> 12936.5 | G36: =G28+G34 -> 26453.5 | H36: =H28+H34 -> 16951.5 | I36: =I28+I34 -> 8903.5 | ... M36: =M28+M34 -> 0
A38: EQUITY
A39: Share Capital / Paid-In Capital | B39: 185000 | C39: 185000 | D39: 185000 | E39: 185000 | F39: 185000 | G39: 185000 | H39: 185000 | I39: 185000 | J39: 185000 | K39: 185000 | L39: 185000 | M39: 185000
A40: Share Premium
A41: Accumulated Deficit / Retained Earnings | B41: ='Income Statement'!B177 -> -21890.392 | C41: ='Income Statement'!C177 -> -33575.946 | D41: ='Income Statement'!D177 -> -25089.493 | E41: ='Income Statement'!E177 -> -36983.802 | F41: ='Income Statement'!F177 -> -58542.378 | G41: ='Income Statement'!G177 -> -10822.374 | H41: ='Income Statement'!H177 -> -24031.839 | I41: ='Income Statement'!I177 -> -31647.264 | ... M41: ='Income Statement'!M177 -> -40616.256
A42: Other Comprehensive Income
A43: TOTAL EQUITY | B43: =B39+B40+B41+B42 -> 163109.61 | C43: =C39+C40+C41+C42 -> 151424.05 | D43: =D39+D40+D41+D42 -> 159910.51 | E43: =E39+E40+E41+E42 -> 148016.2 | F43: =F39+F40+F41+F42 -> 126457.62 | G43: =G39+G40+G41+G42 -> 174177.63 | H43: =H39+H40+H41+H42 -> 160968.16 | I43: =I39+I40+I41+I42 -> 153352.74 | ... M43: =M39+M40+M41+M42 -> 144383.74
A45: TOTAL LIABILITIES & EQUITY | B45: =B36+B43 -> 169049.61 | C45: =C36+C43 -> 154458.05 | D45: =D36+D43 -> 163227.51 | E45: =E36+E43 -> 156415.2 | F45: =F36+F43 -> 139394.12 | G45: =G36+G43 -> 200631.13 | H45: =H36+H43 -> 177919.66 | I45: =I36+I43 -> 162256.24 | ... M45: =M36+M43 -> 144383.74
A47: ⚖ Balance Check (Total Assets − Total Liabilities & Equity) → must equal zero
B48: =B19-B45 -> 0 | C48: =C19-C45 -> 0 | D48: =D19-D45 -> 0 | E48: =E19-E45 -> 0 | F48: =F19-F45 -> 0 | G48: =G19-G45 -> 0 | H48: =H19-H45 -> 0 | I48: =I19-I45 -> 0 | ... M48: =M19-M45 -> -1731.5
...

Sheet Cash Flow
A1: IEPPAL — CASH FLOW STATEMENT
A2: All figures in SGD. Indirect method. Green cells = linked from Income Statement. Blue cells = manual inputs. Populate each quarter-end. | N2: 1 SGD ≈ 0.74 USD as at Jun 2026
B3: YEAR 1 | F3: YEAR 2 | J3: YEAR 3
B4: Q1 | C4: Q2 | D4: Q3 | E4: Q4 | F4: Q1 | G4: Q2 | H4: Q3 | I4: Q4 | J4: Q1 | K4: Q2 | L4: Q3 | M4: Q4
A5: OPERATING ACTIVITIES
A6: Net Income / (Loss) [IS row 175 — after EBITDA, interest, tax] | B6: ='Income Statement'!B176 -> -21890.392 | C6: ='Income Statement'!C176 -> -11685.554 | D6: ='Income Statement'!D176 -> 8486.4528 | E6: ='Income Statement'!E176 -> -11894.309 | F6: ='Income Statement'!F176 -> -21558.576 | G6: ='Income Statement'!G176 -> 47720.003 | H6: ='Income Statement'!H176 -> -13209.465 | I6: ='Income Statement'!I176 -> -7615.4248 | ... M6: ='Income Statement'!M176 -> 237.73922
A7: Add: Depreciation & Amortisation | B7: ='Income Statement'!B138 -> 0 | C7: ='Income Statement'!C138 -> 0 | D7: ='Income Statement'!D138 -> 0 | E7: ='Income Statement'!E138 -> 0 | F7: ='Income Statement'!F138 -> 0 | G7: ='Income Statement'!G138 -> 0 | H7: ='Income Statement'!H138 -> 0 | I7: ='Income Statement'!I138 -> 0 | ... M7: ='Income Statement'!M138 -> 0
A8: Changes in Working Capital
A9: (Increase) / Decrease in Accounts Receivable
A10: Increase / (Decrease) in Deferred Revenue | B10: ='Balance Sheet'!B54 -> 5940 | C10: ='Balance Sheet'!C54-'Balance Sheet'!B54 -> -2906 | D10: ='Balance Sheet'!D54-'Balance Sheet'!C54 -> 283 | E10: ='Balance Sheet'!E54-'Balance Sheet'!D54 -> 5082 | F10: ='Balance Sheet'!F54-'Balance Sheet'!E54 -> 4537.5 | G10: ='Balance Sheet'!G54-'Balance Sheet'!F54 -> 13517 | H10: ='Balance Sheet'!H54-'Balance Sheet'!G54 -> -9502 | I10: ='Balance Sheet'!I54-'Balance Sheet'!H54 -> -8048 | J10: ='Balance Sheet'!J54-'Balance Sheet'!I54 -> 15040 | ... M10: ='Balance Sheet'!M54-'Balance Sheet'!L54 -> -15372
A11: Increase / (Decrease) in Accounts Payable
A12: Other Working Capital Changes
A13: Net Cash from Operating Activities | B13: =B6+B7+B9+B10+B11+B12 -> -15950.392 | C13: =C6+C7+C9+C10+C11+C12 -> -14591.554 | D13: =D6+D7+D9+D10+D11+D12 -> 8769.4528 | E13: =E6+E7+E9+E10+E11+E12 -> -6812.3088 | F13: =F6+F7+F9+F10+F11+F12 -> -17021.076 | G13: =G6+G7+G9+G10+G11+G12 -> 61237.003 | H13: =H6+H7+H9+H10+H11+H12 -> -22711.465 | I13: =I6+I7+I9+I10+I11+I12 -> -15663.425 | ... M13: =M6+M7+M9+M10+M11+M12 -> -15134.261
A15: INVESTING ACTIVITIES
A16: Purchase of Property, Plant & Equipment
A17: Capitalised Software Development Costs
A18: Other Investing Activities
A19: Net Cash from Investing Activities | B19: =B16+B17+B18 -> 0 | C19: =C16+C17+C18 -> 0 | D19: =D16+D17+D18 -> 0 | E19: =E16+E17+E18 -> 0 | F19: =F16+F17+F18 -> 0 | G19: =G16+G17+G18 -> 0 | H19: =H16+H17+H18 -> 0 | I19: =I16+I17+I18 -> 0 | ... M19: =M16+M17+M18 -> 0
A21: FINANCING ACTIVITIES
A22: Proceeds from Share Issuance | B22: 185000
A23: Proceeds from Borrowings
A24: Repayment of Borrowings
A25: Dividends Paid
A26: Net Cash from Financing Activities | B26: =B22+B23+B24+B25 -> 185000 | C26: =C22+C23+C24+C25 -> 0 | D26: =D22+D23+D24+D25 -> 0 | E26: =E22+E23+E24+E25 -> 0 | F26: =F22+F23+F24+F25 -> 0 | G26: =G22+G23+G24+G25 -> 0 | H26: =H22+H23+H24+H25 -> 0 | I26: =I22+I23+I24+I25 -> 0 | ... M26: =M22+M23+M24+M25 -> 0
A28: CASH MOVEMENT SUMMARY
A29: Net Change in Cash | B29: =B13+B19+B26 -> 169049.61 | C29: =C13+C19+C26 -> -14591.554 | D29: =D13+D19+D26 -> 8769.4528 | E29: =E13+E19+E26 -> -6812.3088 | F29: =F13+F19+F26 -> -17021.076 | G29: =G13+G19+G26 -> 61237.003 | H29: =H13+H19+H26 -> -22711.465 | I29: =I13+I19+I26 -> -15663.425 | ... M29: =M13+M19+M26 -> -15134.261
A30: Beginning Cash Balance | B30: 0 | C30: =B31 -> 169049.61 | D30: =C31 -> 154458.05 | E30: =D31 -> 163227.51 | F30: =E31 -> 156415.2 | G30: =F31 -> 139394.12 | H30: =G31 -> 200631.13 | I30: =H31 -> 177919.66 | J30: =I31 -> 162256.24 | ... M30: =L31 -> 157786.5
A31: ENDING CASH BALANCE | B31: =B29+B30 -> 169049.61 | C31: =C29+C30 -> 154458.05 | D31: =D29+D30 -> 163227.51 | E31: =E29+E30 -> 156415.2 | F31: =F29+F30 -> 139394.12 | G31: =G29+G30 -> 200631.13 | H31: =H29+H30 -> 177919.66 | I31: =I29+I30 -> 162256.24 | ... M31: =M29+M30 -> 142652.24
A32: Months of Runway Remaining (informational) | B32: =IFERROR(B31/ABS(AVERAGE(B29,B29,B29,B29))*3,"-") -> 3 | C32: =IFERROR(C31/ABS(AVERAGE(B29))*3,"-") -> 2.7410543 | D32: =IFERROR(D31/ABS(AVERAGE(B29,C29))*3,"-") -> 6.3406538 | E32: =IFERROR(E31/ABS(AVERAGE(B29,C29,D29))*3,"-") -> 8.6243845 | F32: =IFERROR(F31/ABS(AVERAGE(B29,C29,D29,E29))*3,"-") -> 10.694162 | G32: =IFERROR(G31/ABS(AVERAGE(C29,D29,E29,F29))*3,"-") -> 81.184761 | H32: =IFERROR(H31/ABS(AVERAGE(D29,E29,F29,G29))*3,"-") -> 46.239851 | I32: =IFERROR(I31/ABS(AVERAGE(E29,F29,G29,H29))*3,"-") -> 132.52481 | J32: =IFERROR(J31/ABS(AVERAGE(F29,G29,H29,I29))*3,"-") -> 336.14582 | K32: =IFERROR(K31/ABS(AVERAGE(G29,H29,I29,J29))*3,"-") -> 78.906734 | L32: =IFERROR(L31/ABS(AVERAGE(H29,I29,J29,K29))*3,"-") -> 45.810252 | M32: =IFERROR(M31/ABS(AVERAGE(I29,J29,K29,L29))*3,"-") -> 85.025265
A33: Minimum Cash Floor (SGD 25,000) — flag if ending cash falls below | B33: 25000 | C33: 25000 | D33: 25000 | E33: 25000 | F33: 25000 | G33: 25000 | H33: 25000 | I33: 25000 | J33: 25000 | K33: 25000 | L33: 25000 | M33: 25000

Sheet Headcount Plan
A1: IEPPAL — HEADCOUNT PLAN (All figures in SGD/month per head)
A2: Hiring Location Note: India-based roles ≈ 60–70 % cost saving vs. equivalent Singapore roles.
A3: Department | B3: Role | C3: Monthly Salary (SGD) | D3: Y1 Q1 | E3: Y1 Q2 | F3: Y1 Q3 | G3: Y1 Q4 | H3: Y2 Q1 | I3: Y2 Q2 | J3: Y2 Q3 | K3: Y2 Q4 | L3: Y3 Q1 | M3: Y3 Q2 | N3: Y3 Q3 | O3: Y3 Q4
A4: Engineering
B5: Software Engineer (India) | C5: 3400 | D5: 1 | E5: 1 | F5: 1 | G5: 1 | H5: 1 | I5: 1 | J5: 2 | K5: 2 | L5: 2 | M5: 2 | N5: 3 | O5: 3
A6: R&D / AI
B7: R&D Lead (India) | C7: 4250 | D7: 0 | E7: 0 | F7: 0 | G7: 0 | H7: 1 | I7: 1 | J7: 1 | K7: 1 | L7: 1 | M7: 1 | N7: 1 | O7: 1
B8: AI Dev Engineer (India) | C8: 3400 | D8: 0 | E8: 0 | F8: 0 | G8: 0 | H8: 0 | I8: 0 | J8: 0 | K8: 0 | L8: 0 | M8: 0 | N8: 0 | O8: 0
A9: Marketing
B10: Marketing Lead (India) | C10: 4750 | D10: 0 | E10: 0 | F10: 0 | G10: 0 | H10: 0 | I10: 0 | J10: 1 | K10: 1 | L10: 1 | M10: 1 | N10: 1 | O10: 1
A11: Sales & Partnerships
B12: Sales & Partnerships Lead (SG) | C12: 8000 | D12: 0 | E12: 0 | F12: 0 | G12: 0 | H12: 0 | I12: 0 | J12: 0 | K12: 0 | L12: 1 | M12: 1 | N12: 1 | O12: 1
A13: TOTAL HEADCOUNT
A15: TOTAL QUARTERLY SALARY COST (SGD) | D15: =C5*D5+C7*D7+C8*D8+C10*D10+C12*D12 -> 3400 | E15: =C5*E5+C7*E7+C8*E8+C10*E10+C12*E12 -> 3400 | F15: =C5*F5+C7*F7+C8*F8+C10*F10+C12*F12 -> 3400 | G15: =C5*G5+C7*G7+C8*G8+C10*G10+C12*G12 -> 3400 | H15: =C5*H5+C7*H7+C8*H8+C10*H10+C12*H12 -> 7650 | I15: =C5*I5+C7*I7+C8*I8+C10*I10+C12*I12 -> 7650 | J15: =C5*J5+C7*J7+C8*J8+C10*J10+C12*J12 -> 15800 | K15: =C5*K5+C7*K7+C8*K8+C10*K10+C12*K12 -> 15800 | L15: =C5*L5+C7*L7+C8*L8+C10*L10+C12*L12 -> 23800 | M15: =C5*M5+C7*M7+C8*M8+C10*M10+C12*M12 -> 23800 | N15: =C5*N5+C7*N7+C8*N8+C10*N10+C12*N12 -> 27200 | O15: =C5*O5+C7*O7+C8*O8+C10*O10+C12*O12 -> 27200

Sheet ARR Waterfall
A1: IEPPAL — ARR WATERFALL
A3: Metric | B3: Y1 Q1 | C3: Y1 Q2 | D3: Y1 Q3 | E3: Y1 Q4 | F3: Y2 Q1 | G3: Y2 Q2 | H3: Y2 Q3 | I3: Y2 Q4 | J3: Y3 Q1 | K3: Y3 Q2 | L3: Y3 Q3 | M3: Y3 Q4
A5: ARR BY TIER (quarterly revenue × 4)
A6: Basic ARR | B6: ='Income Statement'!B20*4 -> 4800 | C6: ='Income Statement'!C20*4 -> 4800 | D6: ='Income Statement'!D20*4 -> 5700 | E6: ='Income Statement'!E20*4 -> 6600 | F6: ='Income Statement'!F20*4 -> 7050 | G6: ='Income Statement'!G20*4 -> 7500 | H6: ='Income Statement'!H20*4 -> 10488 | I6: ='Income Statement'!I20*4 -> 12984 | ... M6: ='Income Statement'!M20*4 -> 29640
A7: Schools ARR | B7: ='Income Statement'!B33*4 -> 6920 | C7: ='Income Statement'!C33*4 -> 6824 | D7: ='Income Statement'!D33*4 -> 6728 | E7: ='Income Statement'!E33*4 -> 8552 | F7: ='Income Statement'!F33*4 -> 10280 | G7: ='Income Statement'!G33*4 -> 11912 | H7: ='Income Statement'!H33*4 -> 15248 | I7: ='Income Statement'!I33*4 -> 17384 | ... M7: ='Income Statement'!M33*4 -> 40264
A8: Custom ARR | B8: ='Income Statement'!B50*4 -> 0 | C8: ='Income Statement'!C50*4 -> 0 | D8: ='Income Statement'!D50*4 -> 0 | E8: ='Income Statement'!E50*4 -> 0 | F8: ='Income Statement'!F50*4 -> 0 | G8: ='Income Statement'!G50*4 -> 44640 | H8: ='Income Statement'!H50*4 -> 47752 | I8: ='Income Statement'!I50*4 -> 50864 | ... M8: ='Income Statement'!M50*4 -> 106384
A9: Total ARR | B9: =B6+B7+B8 -> 11720 | C9: =C6+C7+C8 -> 11624 | D9: =D6+D7+D8 -> 12428 | E9: =E6+E7+E8 -> 15152 | F9: =F6+F7+F8 -> 17330 | G9: =G6+G7+G8 -> 64052 | H9: =H6+H7+H8 -> 73488 | I9: =I6+I7+I8 -> 81232 | ... M9: =M6+M7+M8 -> 176288
A11: ARR MOVEMENT WATERFALL
A12: Beginning ARR | B12: 0 | C12: =B16 -> 8870 | D12: =C16 -> 8980.1 | E12: =D16 -> 12467.015 | F12: =E16 -> 21251.904 | G12: =F16 -> 29743.469 | H12: =G16 -> 58608.696 | I12: =H16 -> 69072.421 | J12: =I16 -> 82918.8 | ... M12: =L16 -> 189697.37
A13: + New ARR (from new school contracts) | B13: 8870 | C13: 0 | D13: 3390 | E13: 8870 | F13: 8870 | G13: 29530 | H13: 8870 | I13: 12260 | J13: 38400 | K13: 38400 | L13: 26610 | M13: 28700
A14: + Expansion ARR (8% net expansion on Schools + Custom) | B14: 0 | C14: =(B7+B8)*'Key Assumptions'!C17 -> 553.6 | D14: =(C7+C8)*'Key Assumptions'!C17 -> 545.92 | E14: =(D7+D8)*'Key Assumptions'!C17 -> 538.24 | F14: =(E7+E8)*'Key Assumptions'!C17 -> 684.16 | G14: =(F7+F8)*'Key Assumptions'!C17 -> 822.4 | H14: =(G7+G8)*'Key Assumptions'!C17 -> 4524.16 | I14: =(H7+H8)*'Key Assumptions'!C17 -> 5040 | J14: =(I7+I8)*'Key Assumptions'!C17 -> 5459.84 | K14: =(J7+J8)*'Key Assumptions'!C17 -> 6236.8 | L14: =(K7+K8)*'Key Assumptions'!C17 -> 10006.4 | M14: =(L7+L8)*'Key Assumptions'!C17 -> 10706.88
A15: - Churned ARR | B15: 0 | C15: =C12*'Key Assumptions'!C16 -> 443.5 | D15: =D12*'Key Assumptions'!C16 -> 449.005 | E15: =E12*'Key Assumptions'!C16 -> 623.35075 | F15: =F12*'Key Assumptions'!C16 -> 1062.5952 | G15: =G12*'Key Assumptions'!C16 -> 1487.1735 | H15: =H12*'Key Assumptions'!C16 -> 2930.4348 | I15: =I12*'Key Assumptions'!C16 -> 3453.621 | J15: =J12*'Key Assumptions'!C16 -> 4145.94 | K15: =K12*'Key Assumptions'!C16 -> 6131.635 | L15: =L12*'Key Assumptions'!C16 -> 8056.8932 | M15: =M12*'Key Assumptions'!C16 -> 9484.8686
A16: Ending ARR | B16: =B12+B13+B14-B15 -> 8870 | C16: =C12+C13+C14-C15 -> 8980.1 | D16: =D12+D13+D14-D15 -> 12467.015 | E16: =E12+E13+E14-E15 -> 21251.904 | F16: =F12+F13+F14-F15 -> 29743.469 | G16: =G12+G13+G14-G15 -> 58608.696 | H16: =H12+H13+H14-H15 -> 69072.421 | I16: =I12+I13+I14-I15 -> 82918.8 | ... M16: =M12+M13+M14-M15 -> 219619.38
A17: Net New ARR | B17: =B16-B12 -> 8870 | C17: =C16-C12 -> 110.1 | D17: =D16-D12 -> 3486.915 | E17: =E16-E12 -> 8784.8892 | F17: =F16-F12 -> 8491.5648 | G17: =G16-G12 -> 28865.227 | H17: =H16-H12 -> 10463.725 | I17: =I16-I12 -> 13846.379 | ... M17: =M16-M12 -> 29922.011
A19: MRR
A20: Beginning MRR | B20: =B12/12 -> 0 | C20: =C12/12 -> 739.16667 | D20: =D12/12 -> 748.34167 | E20: =E12/12 -> 1038.9179 | F20: =F12/12 -> 1770.992 | G20: =G12/12 -> 2478.6224 | H20: =H12/12 -> 4884.058 | I20: =I12/12 -> 5756.0351 | ... M20: =M12/12 -> 15808.114
A21: Ending MRR | B21: =B16/12 -> 739.16667 | C21: =C16/12 -> 748.34167 | D21: =D16/12 -> 1038.9179 | E21: =E16/12 -> 1770.992 | F21: =F16/12 -> 2478.6224 | G21: =G16/12 -> 4884.058 | H21: =H16/12 -> 5756.0351 | I21: =I16/12 -> 6909.9 | ... M21: =M16/12 -> 18301.615
A22: Net New MRR | B22: =B17/12 -> 739.16667 | C22: =C17/12 -> 9.175 | D22: =D17/12 -> 290.57625 | E22: =E17/12 -> 732.0741 | F22: =F17/12 -> 707.6304 | G22: =G17/12 -> 2405.4355 | H22: =H17/12 -> 871.9771 | I22: =I17/12 -> 1153.8649 | ... M22: =M17/12 -> 2493.501
A24: RATIOS
A25: ARR Growth QoQ % | B25: - | C25: =IFERROR((C16-C12)/C12,"-") -> 0.012412627 | D25: =IFERROR((D16-D12)/D12,"-") -> 0.38829356 | E25: =IFERROR((E16-E12)/E12,"-") -> 0.70465057 | F25: =IFERROR((F16-F12)/F12,"-") -> 0.39956724 | G25: =IFERROR((G16-G12)/G12,"-") -> 0.97047276 | H25: =IFERROR((H16-H12)/H12,"-") -> 0.17853537 | I25: =IFERROR((I16-I12)/I12,"-") -> 0.20046176 | J25: =IFERROR((J16-J12)/J12,"-") -> 0.47894929 | ... M25: =IFERROR((M16-M12)/M12,"-") -> 0.15773551
A26: Gross Churn Rate | B26: 0 | C26: =IFERROR(C15/C12,0) -> 0.05 | D26: =IFERROR(D15/D12,0) -> 0.05 | E26: =IFERROR(E15/E12,0) -> 0.05 | F26: =IFERROR(F15/F12,0) -> 0.05 | G26: =IFERROR(G15/G12,0) -> 0.05 | H26: =IFERROR(H15/H12,0) -> 0.05 | I26: =IFERROR(I15/I12,0) -> 0.05 | J26: =IFERROR(J15/J12,0) -> 0.05 | ... M26: =IFERROR(M15/M12,0) -> 0.05
A27: NRR (Net Revenue Retention) | B27: - | C27: =IFERROR((C12+C14-C15)/C12,"-") -> 1.0124126 | D27: =IFERROR((D12+D14-D15)/D12,"-") -> 1.0107922 | E27: =IFERROR((E12+E14-E15)/E12,"-") -> 0.99317313 | F27: =IFERROR((F12+F14-F15)/F12,"-") -> 0.98219288 | G27: =IFERROR((G12+G14-G15)/G12,"-") -> 0.97764977 | H27: =IFERROR((H12+H14-H15)/H12,"-") -> 1.0271926 | I27: =IFERROR((I12+I14-I15)/I12,"-") -> 1.0229669 | J27: =IFERROR((J12+J14-J15)/J12,"-") -> 1.0158456 | ... M27: =IFERROR((M12+M14-M15)/M12,"-") -> 1.0064419
A28: Quick Ratio | B28: - | C28: =IFERROR((C13+C14)/C15,"-") -> 1.2482525 | D28: =IFERROR((D13+D14)/D15,"-") -> 8.7658712 | E28: =IFERROR((E13+E14)/E15,"-") -> 15.093011 | F28: =IFERROR((F13+F14)/F15,"-") -> 8.9913449 | G28: =IFERROR((G13+G14)/G15,"-") -> 20.409455 | H28: =IFERROR((H13+H14)/H15,"-") -> 4.5707074 | I28: =IFERROR((I13+I14)/I15,"-") -> 5.0092352 | J28: =IFERROR((J13+J14)/J15,"-") -> 10.578986 | ... M28: =IFERROR((M13+M14)/M15,"-") -> 4.1547102
A30: BENCHMARKS: NRR>100%=best-in-class | NRR 90-100%=acceptable early-stage | QuickRatio>4=high-growth | Target NRR>100% by Y2Q3

Sheet Account Waterfall
A1: IEPPAL — ACCOUNT WATERFALL (School Contracts / Logos)
A2: Tracks contracts, not students. B2B school procurement: 3-6 month cycle, 3-quarter lead-to-revenue lag.
A3: Metric | B3: Y1 Q1 | C3: Y1 Q2 | D3: Y1 Q3 | E3: Y1 Q4 | F3: Y2 Q1 | G3: Y2 Q2 | H3: Y2 Q3 | I3: Y2 Q4 | J3: Y3 Q1 | K3: Y3 Q2 | L3: Y3 Q3 | M3: Y3 Q4
A5: ── Basic Tier ──
A6: Basic — Beginning accounts | B6: 0 | C6: =B9 -> 1 | D6: =C9 -> 1 | E6: =D9 -> 2 | F6: =E9 -> 3 | G6: =F9 -> 4 | H6: =G9 -> 5 | I6: =H9 -> 6 | J6: =I9 -> 8 | ... M6: =L9 -> 13
A7: Basic — + New accounts won | B7: 1 | C7: 0 | D7: 1 | E7: 1 | F7: 1 | G7: 1 | H7: 1 | I7: 2 | J7: 2 | K7: 2 | L7: 3 | M7: 2
A8: Basic — - Churned accounts | B8: 0 | C8: =ROUND(C6*'Key Assumptions'!C16,0) -> 0 | D8: =ROUND(D6*'Key Assumptions'!C16,0) -> 0 | E8: =ROUND(E6*'Key Assumptions'!C16,0) -> 0 | F8: =ROUND(F6*'Key Assumptions'!C16,0) -> 0 | G8: =ROUND(G6*'Key Assumptions'!C16,0) -> 0 | H8: =ROUND(H6*'Key Assumptions'!C16,0) -> 0 | I8: =ROUND(I6*'Key Assumptions'!C16,0) -> 0 | J8: =ROUND(J6*'Key Assumptions'!C16,0) -> 0 | K8: =ROUND(K6*'Key Assumptions'!C16,0) -> 1 | L8: =ROUND(L6*'Key Assumptions'!C16,0) -> 1 | M8: =ROUND(M6*'Key Assumptions'!C16,0) -> 1
A9: Basic — = Ending accounts | B9: =B6+B7-B8 -> 1 | C9: =C6+C7-C8 -> 1 | D9: =D6+D7-D8 -> 2 | E9: =E6+E7-E8 -> 3 | F9: =F6+F7-F8 -> 4 | G9: =G6+G7-G8 -> 5 | H9: =H6+H7-H8 -> 6 | I9: =I6+I7-I8 -> 8 | ... M9: =M6+M7-M8 -> 14
A10: ── Schools Tier ──
A11: Schools — Beginning accounts | B11: 0 | C11: =B14 -> 1 | D11: =C14 -> 1 | E11: =D14 -> 1 | F11: =E14 -> 2 | G11: =F14 -> 3 | H11: =G14 -> 4 | I11: =H14 -> 5 | J11: =I14 -> 6 | ... M11: =L14 -> 12
A12: Schools — + New accounts won | B12: 1 | C12: 0 | D12: 0 | E12: 1 | F12: 1 | G12: 1 | H12: 1 | I12: 1 | J12: 2 | K12: 2 | L12: 3 | M12: 4
A13: Schools — - Churned accounts | B13: 0 | C13: =ROUND(C11*'Key Assumptions'!C16,0) -> 0 | D13: =ROUND(D11*'Key Assumptions'!C16,0) -> 0 | E13: =ROUND(E11*'Key Assumptions'!C16,0) -> 0 | F13: =ROUND(F11*'Key Assumptions'!C16,0) -> 0 | G13: =ROUND(G11*'Key Assumptions'!C16,0) -> 0 | H13: =ROUND(H11*'Key Assumptions'!C16,0) -> 0 | I13: =ROUND(I11*'Key Assumptions'!C16,0) -> 0 | J13: =ROUND(J11*'Key Assumptions'!C16,0) -> 0 | K13: =ROUND(K11*'Key Assumptions'!C16,0) -> 0 | L13: =ROUND(L11*'Key Assumptions'!C16,0) -> 1 | M13: =ROUND(M11*'Key Assumptions'!C16,0) -> 1
A14: Schools — = Ending accounts | B14: =B11+B12-B13 -> 1 | C14: =C11+C12-C13 -> 1 | D14: =D11+D12-D13 -> 1 | E14: =E11+E12-E13 -> 2 | F14: =F11+F12-F13 -> 3 | G14: =G11+G12-G13 -> 4 | H14: =H11+H12-H13 -> 5 | I14: =I11+I12-I13 -> 6 | ... M14: =M11+M12-M13 -> 15
A15: ── Custom Tier ──
A16: Custom — Beginning accounts | B16: 0 | C16: =B19 -> 0 | D16: =C19 -> 0 | E16: =D19 -> 0 | F16: =E19 -> 0 | G16: =F19 -> 0 | H16: =G19 -> 1 | I16: =H19 -> 1 | J16: =I19 -> 1 | ... M16: =L19 -> 3
A17: Custom — + New accounts won | B17: 0 | C17: 0 | D17: 0 | E17: 0 | F17: 0 | G17: 1 | H17: 0 | I17: 0 | J17: 1 | K17: 1 | L17: 0 | M17: 0
A18: Custom — - Churned accounts | B18: 0 | C18: =ROUND(C16*'Key Assumptions'!C16,0) -> 0 | D18: =ROUND(D16*'Key Assumptions'!C16,0) -> 0 | E18: =ROUND(E16*'Key Assumptions'!C16,0) -> 0 | F18: =ROUND(F16*'Key Assumptions'!C16,0) -> 0 | G18: =ROUND(G16*'Key Assumptions'!C16,0) -> 0 | H18: =ROUND(H16*'Key Assumptions'!C16,0) -> 0 | I18: =ROUND(I16*'Key Assumptions'!C16,0) -> 0 | J18: =ROUND(J16*'Key Assumptions'!C16,0) -> 0 | K18: =ROUND(K16*'Key Assumptions'!C16,0) -> 0 | L18: =ROUND(L16*'Key Assumptions'!C16,0) -> 0 | M18: =ROUND(M16*'Key Assumptions'!C16,0) -> 0
A19: Custom — = Ending accounts | B19: =B16+B17-B18 -> 0 | C19: =C16+C17-C18 -> 0 | D19: =D16+D17-D18 -> 0 | E19: =E16+E17-E18 -> 0 | F19: =F16+F17-F18 -> 0 | G19: =G16+G17-G18 -> 1 | H19: =H16+H17-H18 -> 1 | I19: =I16+I17-I18 -> 1 | ... M19: =M16+M17-M18 -> 3
A20: ── SALES FUNNEL ──
A21: Lead-to-close lag: 2 qtrs | Contract-to-revenue: 1 qtr | Total lead-to-revenue: 3 qtrs | Close rate: 20%
A22: Implied leads — Basic | B22: 5 | C22: 0 | D22: 5 | E22: 5 | F22: 5 | G22: 5 | H22: 5 | I22: 10 | J22: 10 | K22: 10 | L22: 15 | M22: 10
A23: Implied leads — Schools | B23: 5 | C23: 0 | D23: 0 | E23: 5 | F23: 5 | G23: 5 | H23: 5 | I23: 5 | J23: 10 | K23: 10 | L23: 15 | M23: 20
A24: Implied leads — Custom | B24: 0 | C24: 0 | D24: 0 | E24: 0 | F24: 0 | G24: 5 | H24: 0 | I24: 0 | J24: 5 | K24: 5 | L24: 0 | M24: 0
A26: ── AGGREGATE ──
A27: Total accounts (all tiers) | B27: =B8+B13+B18 -> 0 | C27: =C8+C13+C18 -> 0 | D27: =D8+D13+D18 -> 0 | E27: =E8+E13+E18 -> 0 | F27: =F8+F13+F18 -> 0 | G27: =G8+G13+G18 -> 0 | H27: =H8+H13+H18 -> 0 | I27: =I8+I13+I18 -> 0 | ... M27: =M8+M13+M18 -> 2
A28: Total students (all tiers) | B28: ='Income Statement'!B9+'Income Statement'!B25+'Income Statement'!B38 -> 35 | C28: ='Income Statement'!C9+'Income Statement'!C25+'Income Statement'!C38 -> 34 | D28: ='Income Statement'!D9+'Income Statement'!D25+'Income Statement'!D38 -> 33 | E28: ='Income Statement'!E9+'Income Statement'!E25+'Income Statement'!E38 -> 52 | F28: ='Income Statement'!F9+'Income Statement'!F25+'Income Statement'!F38 -> 70 | G28: ='Income Statement'!G9+'Income Statement'!G25+'Income Statement'!G38 -> 117 | H28: ='Income Statement'!H9+'Income Statement'!H25+'Income Statement'!H38 -> 132 | I28: ='Income Statement'!I9+'Income Statement'!I25+'Income Statement'!I38 -> 147 | ... M28: ='Income Statement'!M9+'Income Statement'!M25+'Income Statement'!M38 -> 383
A29: ARPA per quarter (SGD) | B29: =IFERROR('Income Statement'!B52/B27,0) -> 0 | C29: =IFERROR('Income Statement'!C52/C27,0) -> 0 | D29: =IFERROR('Income Statement'!D52/D27,0) -> 0 | E29: =IFERROR('Income Statement'!E52/E27,0) -> 0 | F29: =IFERROR('Income Statement'!F52/F27,0) -> 0 | G29: =IFERROR('Income Statement'!G52/G27,0) -> 0 | H29: =IFERROR('Income Statement'!H52/H27,0) -> 0 | I29: =IFERROR('Income Statement'!I52/I27,0) -> 0 | ... M29: =IFERROR('Income Statement'!M52/M27,0) -> 22036
A30: ARPA annualised (SGD) | B30: =B29*4 -> 0 | C30: =C29*4 -> 0 | D30: =D29*4 -> 0 | E30: =E29*4 -> 0 | F30: =F29*4 -> 0 | G30: =G29*4 -> 0 | H30: =H29*4 -> 0 | I30: =I29*4 -> 0 | ... M30: =M29*4 -> 88144
